Workbook
Name Beginning_Balance: -FV('Map Counties'!Interest_Rate/12,'Map Counties'!Payment_Number-1,-'Map Counties'!Monthly_Payment,'Map Counties'!Loan_Amount)
Name Beginning_Balance: -FV(Interest_Rate/12,'Wealth Creation Calc'!Payment_Number-1,-'Wealth Creation Calc'!Monthly_Payment,Loan_Amount)
Name Beginning_Balance: -FV(Interest_Rate/12,Payment_Number-1,-Monthly_Payment,Loan_Amount)
Name CA: #REF!
Name CaseShiller30: '[1]Case Shiller 30 yr'!$A$4:$R$111
Name CaseShiller30: '[2]Case Shiller 30 yr'!$A$4:$R$111
Name CaseShiller30: #REF!
Name CO: #REF!
Name CO_HomePrices: '[2]CO Home Prices'!$C$2:$J$69
Name CO_HomePrices: #REF!
Name ColumnTitle1: #REF!
Name ColumnTitle1: #REF!
Name ColumnTitle1: [1]!Loan[[#Headers],[No.]]
Name ColumnTitle1: #REF!
Name ColumnTitle1: #REF!
Name ColumnTitle1: [2]!Loan[[#Headers],[No.]]
Name ColumnTitle1: #REF!
Name Delete1: #REF!
Name Delete1: #REF!
Name Delete1: #REF!
Name Delete1: #REF!
Name Delete1: [2]!Loan[[#Headers],[No.]]
Name Delete1: #REF!
Name Delete21: #REF!
Name Delete21: #REF!
Name Delete21: #REF!
Name Delete21: #REF!
Name Delete21: [2]!Loan[[#Headers],[No.]]
Name Delete21: #REF!
Name Ending_Balance: -FV('Map Counties'!Interest_Rate/12,'Map Counties'!Payment_Number,-'Map Counties'!Monthly_Payment,'Map Counties'!Loan_Amount)
Name Ending_Balance: -FV(Interest_Rate/12,'Wealth Creation Calc'!Payment_Number,-'Wealth Creation Calc'!Monthly_Payment,Loan_Amount)
Name Ending_Balance: -FV(Interest_Rate/12,Payment_Number,-Monthly_Payment,Loan_Amount)
Name Full_Print: #REF!
Name Header_Row: ROW(#REF!)
Name Header_Row_Back: ROW('[1]Loan calculator'!$11:$11)
Name Header_Row_Back: ROW('[2]Loan calculator'!$11:$11)
Name Header_Row_Back: ROW(#REF!)
Name HPA: 'Assumptions & Borrower Profiles'!$C$11
Name Interest: -IPMT('Map Counties'!Interest_Rate/12,'Map Counties'!Payment_Number,'Map Counties'!Number_of_Payments,'Map Counties'!Loan_Amount)
Name Interest: -IPMT(Interest_Rate/12,'Wealth Creation Calc'!Payment_Number,Number_of_Payments,Loan_Amount)
Name Interest: -IPMT(Interest_Rate/12,Payment_Number,Number_of_Payments,Loan_Amount)
Name Interest_Rate: #REF!
Name Interest_Rate: #REF!
Name Last_Row: #N/A
Name Last_Row: #N/A
Name Last_Row: IF([3]!Values_Entered,[3]!Header_Row+[3]!Number_of_Payments,[3]!Header_Row)
Name Loan_Amount: #REF!
Name Loan_Amount: #REF!
Name Loan_Not_Paid: IF('Map Counties'!Payment_Number<='Map Counties'!Number_of_Payments,1,0)
Name Loan_Not_Paid: IF('Wealth Creation Calc'!Payment_Number<=Number_of_Payments,1,0)
Name Loan_Not_Paid: IF(Payment_Number<=Number_of_Payments,1,0)
Name Loan_Start: #REF!
Name Loan_Start: #REF!
Name Loan_Years: #REF!
Name Loan_Years: #REF!
Name Model: 'Aggregate Model'!$B$2:$BC$23
Name Model: 'Harper - Aggregate Model'!$B$2:$BC$76
Name Model: 'Remi - Aggregate Model'!$B$2:$BC$76
Name Model: 'Tiana - Aggregate Model'!$B$2:$BC$76
Name Model: '[2]Black & Hispanic Model'!$B$1:$BC$27

Sheet Target Zips List
D3: ## Paste Target Zips below in D4 then flow them thru to Individual Borrowers' Ag Model
D4: Alcona
D5: Alger
D6: Allegan
D7: Alpena
D8: Antrim
D9: Arenac
D10: Baraga
D11: Barry
D12: Bay
D13: Benzie
D14: Berrien
... D86: Wexford

Sheet Assumptions & Borrower Profiles
B1: Assumptions | F1: Hide Cells before Pasting into PPT | K1: Scenario | L1: 1 | M1: 2 | N1: 3
B2: Down Payment % | C2: 0.03 | K2: Name | L2: Cecilia | M2: Adam | N2: Nora
K3: Age | L3: 28 | M3: 32 | N3: 38
B4: Homium SAM % | C4: 0.3 | L4: Registered Nurse | M4: Police Officer | N4: CDL-A Truck Driver
K5: % AMI | L5: 0.8 | M5: 1 | N5: 1.2
B6: Credit Score | C6: 620 | K6: Avg. USD Income | L6: =L5*$C$21 -> 0 | M6: =M5*$C$21 -> 0 | N6: =N5*$C$21 -> 0 | O6: =AVERAGE(L6:N6) -> 0
B7: 1st Mortgage Rate w/o HOM | C7: 0.0625
B8: 1st Mortgage Rate w/ HOM | C8: =C7 -> 0.0625 | K8: % Median Home Price | L8: 1 | M8: 1 | N8: 1.4 | P8: =0.8*L9 -> 0
B9: Mortgage Duration (yrs) | C9: 30 | K9: Home Price | L9: =L8*$C$22 -> 0 | M9: =M8*$C$22 -> 0 | N9: =N8*$C$22 -> 0
B11: Annual HPA % | C11: 0.05 | K11: DP % | L11: =$C$2 -> 0.03 | M11: =$C$2 -> 0.03 | N11: =$C$2 -> 0.03
K12: ="Down Payment ("&C2*100&"%)" -> Down Payment (3%) | L12: =L9*L11 -> 0 | M12: =M9*M11 -> 0 | N12: =N9*N11 -> 0
B13: Closing Costs % | C13: 0.02
K14: Traditional Financing
K15: 1st Mortgage % | L15: =1-L11 -> 0.97 | M15: =1-M11 -> 0.97 | N15: =1-N11 -> 0.97
B16: PMI Rate Est | C16: 0.0117 | K16: ="Conforming 1st Mortgage ("&(1-C2)*100&"%)" -> Conforming 1st Mortgage (97%) | L16: =L15*L9 -> 0 | M16: =M15*M9 -> 0 | N16: =N15*N9 -> 0
B17: Tax/ yr | C17: 0.0135 | K17: Monthly PMT | L17: =PMT($C$7/12,12*$C$9,-L$16) -> 0 | M17: =PMT($C$7/12,12*$C$9,-M$16) -> 0 | N17: =PMT($C$7/12,12*$C$9,-N$16) -> 0
B18: Insurance / yr | C18: 0.004 | K18: Monthly PMI | L18: =L16*$C$16/12 -> 0 | M18: =M16*$C$16/12 -> 0 | N18: =N16*$C$16/12 -> 0
K19: Monthly Tax | L19: =$C$17*L$9/12 -> 0 | M19: =$C$17*M$9/12 -> 0 | N19: =$C$17*N$9/12 -> 0
B20: Median Calc | K20: Monthly Insurance | L20: =$C$18*L9/12 -> 0 | M20: =$C$18*M9/12 -> 0 | N20: =$C$18*N9/12 -> 0
B21: Household Income | C21: ='Aggregate Model'!I25 -> 0 | K21: Total Monthly Payment* | L21: =SUM(L17:L20) -> 0 | M21: =SUM(M17:M20) -> 0 | N21: =SUM(N17:N20) -> 0
B22: Home Value | C22: ='Aggregate Model'!G24 -> 0 | K22: Front Ratio** | L22: =L21/(L6/12) -> #DIV/0! | M22: =M21/(M6/12) -> #DIV/0! | N22: =N21/(N6/12) -> #DIV/0!
B24: Thresholds | K24: With
B25: Front Ratio | C25: 0.35 | K25: 1st Mortgage % | L25: =1-SUM(L27,L11) -> 0.67 | M25: =1-SUM(M27,M11) -> 0.67 | N25: =1-SUM(N27,N11) -> 0.72
K26: ="1st Mortgage with Homium ("&(1-SUM($C$4,$C$2))*100&"%)" -> 1st Mortgage with Homium (67%) | L26: =L25*L9 -> 0 | M26: =M25*M9 -> 0 | N26: =N25*N9 -> 0
K27: Homium % | L27: 0.3 | M27: 0.3 | N27: 0.25
K28: ="2nd Position Homium SAM ("&$C$4*100&"%)" -> 2nd Position Homium SAM (30%) | L28: =L27*L9 -> 0 | M28: =M27*M9 -> 0 | N28: =N27*N9 -> 0 | O28: =AVERAGE(L28:N28) -> 0
K29: Monthly Payment with Homium | L29: =PMT($C$8/12,12*$C$9,-L$26) -> 0 | M29: =PMT($C$8/12,12*$C$9,-M$26) -> 0 | N29: =PMT($C$8/12,12*$C$9,-N$26) -> 0
K30: Total Monthly Payment with Homium* | L30: =L29+SUM(L19:L20) -> 0 | M30: =M29+SUM(M19:M20) -> 0 | N30: =N29+SUM(N19:N20) -> 0
K31: Front Ratio** | L31: =L30/(L$6/12) -> #DIV/0! | M31: =M30/(M$6/12) -> #DIV/0! | N31: =N30/(N$6/12) -> #DIV/0!
K33: Comparison (Traditional vs Homium)
K34: Personal Free Cash Flow*** | L34: =L21-L30 -> 0 | M34: =M21-M30 -> 0 | N34: =N21-N30 -> 0 | O34: =L34*12 -> 0
B36: Program Size | K36: Program Impact
B37: Program Capital | C37: 10000000 | K37: % AMI | L37: =L5 -> 0.8 | M37: =M5 -> 1 | N37: =N5 -> 1.2
A38: 0.05 | B38: Less: Program Fee | C38: =-C37*A38 -> -500000 | K38: Borrower Eligibility w/o Homium | L38: 0.35 | M38: 0.71 | N38: 0.49
B39: Net Capital Invested | C39: =SUM(C37:C38) -> 9500000 | K39: Borrower Eligibility with Homium | L39: 0.84 | M39: 0.94 | N39: 0.84
K40: Increase in Borrower Eligibility | L40: =L39-L38 -> 0.49 | M40: =M39-M38 -> 0.23 | N40: =N39-N38 -> 0.35
K42: # FTHB Homes Created | L42: =$C$39/L28 -> #DIV/0! | M42: =$C$39/M28 -> #DIV/0! | N42: =$C$39/N28 -> #DIV/0!
K44: Total Value of Homes Purchased | L44: =L$42*L9 -> #DIV/0! | M44: =M$42*M9 -> #DIV/0! | N44: =N$42*N9 -> #DIV/0! | O44: =AVERAGE(L44:N44) -> #DIV/0!
K45: Total 1st Mortgage Principal | L45: =L$42*L26 -> #DIV/0! | M45: =M$42*M26 -> #DIV/0! | N45: =N$42*N26 -> #DIV/0! | O45: =AVERAGE(L45:N45) -> #DIV/0!
K46: Total Homeowner Equity created after 10 Years at 5% Home Price Appreciation | L46: =L42*((L9*(1+HPA)^10)-(L28*(1+HPA)^10)-FV($C$8/12,10*12,L29,-L26)) -> #DIV/0! | M46: =M42*((M9*(1+HPA)^10)-(M28*(1+HPA)^10)-FV($C$8/12,10*12,M29,-M26)) -> #DIV/0! | N46: =N42*((N9*(1+HPA)^10)-(N28*(1+HPA)^10)-FV($C$8/12,10*12,N29,-N26)) -> #DIV/0! | O46: =AVERAGE(L46:N46) -> #DIV/0!
...

Sheet Aggregate Model
BS2: Front Ratio | BT2: 0.35
B3: Key Assumptions: | K3: ='Assumptions & Borrower Profiles'!$C$11 -> 0.05 | L3: 1 | M3: 1 | Q3: 0.3 | R3: 1 | X3: ='Assumptions & Borrower Profiles'!L11 -> 0.03 | Y3: ='Assumptions & Borrower Profiles'!$C$7 -> 0.0625 | AA3: ='Assumptions & Borrower Profiles'!$C$6 -> 620 | AC3: ='Assumptions & Borrower Profiles'!$C$18 -> 0.004 | AF3: ='Assumptions & Borrower Profiles'!$C$25 -> 0.35 | AG3: =AF3+0.1 -> 0.45 | AH3: =Q3 -> 0.3 | AI3: ='Assumptions & Borrower Profiles'!C7-'Assumptions & Borrower Profiles'!C8 -> 0 | AK3: 0 | AM3: =AC3 -> 0.004 | AP3: =AF3 -> 0.35 | AQ3: =AG3 -> 0.45 | AR3: 0 | AS3: ='Assumptions & Borrower Profiles'!$C$13 -> 0.02 | AT3: 0.03 | AU3: 0 | BN3: Homium needed | CA3: Affordability Test (Without Homium) | CG3: Homium Needed
B4: County | C4: Code | D4: Population | E4: % African American | F4: Area Median Household Income | G4: Median Home Values | H4: Median Contract Rent | I4: DTI Avg | J4: Estimated Household Debt (incl mortgage) | K4: 30 Year Case Shiller Return / ann | L4: % AMI for calc | M4: % Median Home Value | N4: Passed DTI without HOM? | O4: Passed DTI with HOM? | P4: Threshold? | Q4: HOM Investment | R4: Grant for Fees/PMI | S4: Annual PMI | T4: Homeowner Equity after 10 Years | U4: % Gain from Downpayment | V4: HOM Investment after 10 Years | W4: % Gain on HOM Investment | X4: Downpayment | Y4: 30 Year Fixed Rate for 640 | Z4: 1st Principal Without Homium | AA4: PMI / Month | AB4: Tax / mo | AC4: Insurance / mo | AD4: Household Debt Service / mo | AE4: Monthly Payment | AF4: Front Ratio | AG4: Back Ratio | AH4: SAN Principal | AI4: 30 Year Fixed Rate for 640 WITH HOMIUM | AJ4: 1st Principal WITH Homium | AK4: PMI / Month | AL4: Tax / mo | AM4: Insurance / mo | AN4: Household Debt Service / mo | AO4: New Monthly Payment on 1st | AP4: Front Ratio with HOM | AQ4: Back Ratio with HOM | AR4: PMI Total (yrs) | AS4: Closing Fees | AT4: Origination Fees | AU4: Total Grant | AV4: % Total Grant of Home Value | AW4: Home Value after 10 years at X apprec | AX4: Homium SAN Value after 10 years | AY4: % Gain on HOM investment | AZ4: Homeowner Equity after 10 years | BA4: % Gain from Downpayment | BE4: Max Monthly Payment (PITI) | BF4: Max PI without Hom | BG4: Monthly Rate | BH4: Payment Factor | BI4: Affordable 1st Mortgage Balance without HOM | BK4: Max PI with Hom | BL4: Affordable 1st Mortgage Balance w HOM | BN4: Affordability Gap without Hom | BO4: Hom % | BP4: residual gap after homium (Check) | BS4: State | BT4: AMI | BU4: MHV | BV4: Median Rent | BW4: PMI | BX4: Tax | BY4: Insurance | BZ4: Max Monthly Housing Budget | CA4: Max Principal + Interest Without Hom | CB4: Monthly 1st Mortgage Rate | CC4: Affordable Home Price @ 35% DTI | CD4: Affordability Gap (Problem) | CE4: Affordable 1st Mortgage Without Hom | CG4: Max Principal + Interest With Homium | CH4: Affordable 1st Mortgage with Homium | CI4: Down Payment (3%) | CJ4: Homium Needed ($) | CK4: Homium % | CM4: Affordable Home Price PITI | CN4: 1% Monthly Maintenance | CO4: Total Monthly Ownership Cost | CP4: Median Contract Rent | CQ4: Monthly Delta
B5: Delaware | D5: =_xlfn.XLOOKUP($B5,'Paste Snowflake Data Here'!$B$3:$B$1048576,'Paste Snowflake Data Here'!$D$3:$D$1048576) -> 1043909 | F5: =_xlfn.XLOOKUP($B5,'Paste Snowflake Data Here'!$B$3:$B$1048576,'Paste Snowflake Data Here'!$I$3:$I$1048576) -> 84523 | G5: =_xlfn.XLOOKUP($B5,'Paste Snowflake Data Here'!$B$3:$B$1048576,'Paste Snowflake Data Here'!$J$3:$J$1048576) -> 389964 | H5: =_xlfn.XLOOKUP($B5,'Paste Snowflake Data Here'!$B$3:$B$1048576,'Paste Snowflake Data Here'!$K$3:$K$1048576) -> 1322 | K5: =IFERROR(VLOOKUP(LEFT(B5,FIND("County",B5)-2),CaseShiller30,5,0)*0.01,$K$3) -> 0.05 | L5: =$F5*$L$3 -> 84523 | M5: =$G5*$M$3 -> 389964 | N5: =AND(AF5<$AF$3,AG5<$AG$3) -> FALSE | O5: =AND(AP5<$AP$3,AQ5<$AQ$3) -> TRUE | P5: =AND(N5=FALSE,O5) -> TRUE | Q5: =AH5 -> 116989.2 | R5: =AU5 -> 0 | S5: =AR5 -> 0 | T5: =AZ5 -> 224554.36 | U5: =BA5 -> 19.194452 | V5: =AX5 -> 190563.08 | W5: =AY5 -> 1.6288946 | X5: =$X$3*M5 -> 11698.92 | Y5: =$Y$3 -> 0.0625 | Z5: =M5-X5 -> 378265.08 | AA5: =Z5*'PMI Rate Est'!$J$6/12 -> 368.80845 | AB5: ='Taxes & Ins by State'!B9*M5/12 -> 162.485 | AC5: ='Taxes & Ins by State'!M2*M5/12 -> 80.333333 | AD5: =MAX(J5*Y5/12,0) -> 0 | AE5: =-PMT(Y5/12,360,Z5) -> 2329.0432 | AF5: =SUM(AE5,AC5,AB5,AA5)/(L5/12) -> 0.4174963 | AG5: =SUM(AE5,AC5,AB5,AA5,AD5)/(L5/12) -> 0.4174963 | AH5: =M5*$AH$3 -> 116989.2 | AI5: =Y5+$AI$3 -> 0.0625 | AJ5: =M5-X5-AH5 -> 261275.88 | AK5: =AH5*$AK$3/12 -> 0 | AL5: =AB5 -> 162.485 | AM5: =AC5 -> 80.333333 | AN5: =MAX(J5*Y5/12,0) -> 0 | AO5: =-PMT(AI5/12,360,AJ5) -> 1608.7205 | AP5: =SUM(AO5,AM5,AL5)/(L5/12) -> 0.26286888 | AQ5: =SUM(AO5,AM5,AL5,AK5,AN5)/(L5/12) -> 0.26286888 | AR5: =$AR$3*AK5*12 -> 0 | AS5: =$AS$3*(M5-X5) -> 7565.3016 | AT5: =$AT$3*(AH5) -> 3509.676 | AU5: =$AU$3*SUM(AR5,AS5,AT5) -> 0 | AV5: =AU5/M5 -> 0 | AW5: =POWER(1+K5,10)*M5 -> 635210.26 | AX5: =POWER(1+K5,10)*AH5 -> 190563.08 | AY5: =AX5/AH5 -> 1.6288946 | AZ5: =AW5-AX5-FV(AI5/12,(10*12),AO5,-AJ5) -> 224554.36 | BA5: =AZ5/X5 -> 19.194452 | BE5: =(L5/12)*35% -> 2465.2542 | BF5: =BE5-AC5-AB5-AA5 -> 1853.6274 | BG5: =$Y$3/12 -> 0.0052083333 | BH5: =(BG5*(1+BG5)^360) / (((1+BG5)^360)-1) -> 0.006157172 | BI5: =PV(BG5, 360, -BF5) -> 301051.75 | BK5: =BE5-AB5-AC5 -> 2222.4358 | BL5: =BK5/BH5 -> 360950.75 | BN5: =M5-BI5-X5 -> 77213.334 | BO5: =BN5/M5 -> 0.19800119 | BP5: =M5-BL5-X5 -> 17314.333 | BS5: =B5 -> Delaware | BT5: =L5 -> 84523 | BU5: =M5 -> 389964 | BV5: =H5 -> 1322 | BW5: =AA5 -> 368.80845 | BX5: =AB5 -> 162.485 | BY5: =AC5 -> 80.333333 | BZ5: =(BT5/12)*$BT$2 -> 2465.2542 | CA5: =BZ5-BW5-BX5-BY5 -> 1853.6274 | CB5: =6.25%/12 -> 0.0052083333 | CC5: =CE5/0.97 -> 310362.62 | CD5: =BU5-CC5 -> 79601.376 | CE5: =PV(CB5,360,-CA5) -> 301051.75 | CG5: =BZ5-BY5-BX5 -> 2222.4358 | CH5: =PV(CB5,360,-CG5) -> 360950.75 | CI5: =BU5*0.03 -> 11698.92 | CJ5: =BU5-CI5-CH5 -> 17314.333 | CK5: =CJ5/BU5 -> 0.044399825 | CM5: =CA5 -> 1853.6274 | CN5: =(CC5*1%)/12 -> 258.63552 | CO5: =CM5+CN5+BX5+BY5 -> 2355.0812 | CP5: =VLOOKUP(BS5,'Paste Snowflake Data Here'!$B$2:$K$21,10,FALSE) -> 1322 | CQ5: =CP5-CO5 -> -1033.0812
B6: Hawaii | D6: =_xlfn.XLOOKUP($B6,'Paste Snowflake Data Here'!$B$3:$B$1048576,'Paste Snowflake Data Here'!$D$3:$D$1048576) -> 1480456 | F6: =_xlfn.XLOOKUP($B6,'Paste Snowflake Data Here'!$B$3:$B$1048576,'Paste Snowflake Data Here'!$I$3:$I$1048576) -> 101529 | G6: =_xlfn.XLOOKUP($B6,'Paste Snowflake Data Here'!$B$3:$B$1048576,'Paste Snowflake Data Here'!$J$3:$J$1048576) -> 924013 | H6: =_xlfn.XLOOKUP($B6,'Paste Snowflake Data Here'!$B$3:$B$1048576,'Paste Snowflake Data Here'!$K$3:$K$1048576) -> 1807 | K6: =IFERROR(VLOOKUP(LEFT(B6,FIND("County",B6)-2),CaseShiller30,5,0)*0.01,$K$3) -> 0.05 | L6: =$F6*$L$3 -> 101529 | M6: =$G6*$M$3 -> 924013 | N6: =AND(AF6<$AF$3,AG6<$AG$3) -> FALSE | O6: =AND(AP6<$AP$3,AQ6<$AQ$3) -> FALSE | P6: =AND(N6=FALSE,O6) -> FALSE | Q6: =AH6 -> 277203.9 | R6: =AU6 -> 0 | S6: =AR6 -> 0 | T6: =AZ6 -> 532077.7 | U6: =BA6 -> 19.194452 | V6: =AX6 -> 451535.94 | W6: =AY6 -> 1.6288946 | X6: =$X$3*M6 -> 27720.39 | Y6: =$Y$3 -> 0.0625 | Z6: =M6-X6 -> 896292.61 | AA6: =Z6*'PMI Rate Est'!$J$6/12 -> 873.88529 | AB6: ='Taxes & Ins by State'!B12*M6/12 -> 246.40347 | AC6: ='Taxes & Ins by State'!M3*M6/12 -> 102 | AD6: =MAX(J6*Y6/12,0) -> 0 | AE6: =-PMT(Y6/12,360,Z6) -> 5518.6278 | AF6: =SUM(AE6,AC6,AB6,AA6)/(L6/12) -> 0.79672801 | AG6: =SUM(AE6,AC6,AB6,AA6,AD6)/(L6/12) -> 0.79672801 | AH6: =M6*$AH$3 -> 277203.9 | AI6: =Y6+$AI$3 -> 0.0625 | AJ6: =M6-X6-AH6 -> 619088.71 | AK6: =AH6*$AK$3/12 -> 0 | AL6: =AB6 -> 246.40347 | AM6: =AC6 -> 102 | AN6: =MAX(J6*Y6/12,0) -> 0 | AO6: =-PMT(AI6/12,360,AJ6) -> 3811.8357 | AP6: =SUM(AO6,AM6,AL6)/(L6/12) -> 0.49171044 | AQ6: =SUM(AO6,AM6,AL6,AK6,AN6)/(L6/12) -> 0.49171044 | AR6: =$AR$3*AK6*12 -> 0 | AS6: =$AS$3*(M6-X6) -> 17925.852 | AT6: =$AT$3*(AH6) -> 8316.117 | AU6: =$AU$3*SUM(AR6,AS6,AT6) -> 0 | AV6: =AU6/M6 -> 0 | AW6: =POWER(1+K6,10)*M6 -> 1505119.8 | AX6: =POWER(1+K6,10)*AH6 -> 451535.94 | AY6: =AX6/AH6 -> 1.6288946 | AZ6: =AW6-AX6-FV(AI6/12,(10*12),AO6,-AJ6) -> 532077.7 | BA6: =AZ6/X6 -> 19.194452 | BE6: =(L6/12)*35% -> 2961.2625 | BF6: =BE6-AC6-AB6-AA6 -> 1738.9737 | BG6: =$Y$3/12 -> 0.0052083333 | BH6: =(BG6*(1+BG6)^360) / (((1+BG6)^360)-1) -> 0.006157172 | BI6: =PV(BG6, 360, -BF6) -> 282430.59 | BK6: =BE6-AB6-AC6 -> 2612.859 | BL6: =BK6/BH6 -> 424360.25 | BN6: =M6-BI6-X6 -> 613862.02 | BO6: =BN6/M6 -> 0.66434349 | BP6: =M6-BL6-X6 -> 471932.36 | BS6: =B6 -> Hawaii | BT6: =L6 -> 101529 | BU6: =M6 -> 924013 | BV6: =H6 -> 1807 | BW6: =AA6 -> 873.88529 | BX6: =AB6 -> 246.40347 | BY6: =AC6 -> 102 | BZ6: =(BT6/12)*$BT$2 -> 2961.2625 | CA6: =BZ6-BW6-BX6-BY6 -> 1738.9737 | CB6: =6.25%/12 -> 0.0052083333 | CC6: =CE6/0.97 -> 291165.56 | CD6: =BU6-CC6 -> 632847.44 | CE6: =PV(CB6,360,-CA6) -> 282430.59 | CG6: =BZ6-BY6-BX6 -> 2612.859 | CH6: =PV(CB6,360,-CG6) -> 424360.25 | CI6: =BU6*0.03 -> 27720.39 | CJ6: =BU6-CI6-CH6 -> 471932.36 | CK6: =CJ6/BU6 -> 0.51074212 | CM6: =CA6 -> 1738.9737 | CN6: =(CC6*1%)/12 -> 242.63797 | CO6: =CM6+CN6+BX6+BY6 -> 2330.0152 | CP6: =VLOOKUP(BS6,'Paste Snowflake Data Here'!$B$2:$K$21,10,FALSE) -> 1807 | CQ6: =CP6-CO6 -> -523.01517
B7: Illinois | D7: =_xlfn.XLOOKUP($B7,'Paste Snowflake Data Here'!$B$3:$B$1048576,'Paste Snowflake Data Here'!$D$3:$D$1048576) -> 12439592 | F7: =_xlfn.XLOOKUP($B7,'Paste Snowflake Data Here'!$B$3:$B$1048576,'Paste Snowflake Data Here'!$I$3:$I$1048576) -> 84176 | G7: =_xlfn.XLOOKUP($B7,'Paste Snowflake Data Here'!$B$3:$B$1048576,'Paste Snowflake Data Here'!$J$3:$J$1048576) -> 286497 | H7: =_xlfn.XLOOKUP($B7,'Paste Snowflake Data Here'!$B$3:$B$1048576,'Paste Snowflake Data Here'!$K$3:$K$1048576) -> 1205 | K7: =IFERROR(VLOOKUP(LEFT(B7,FIND("County",B7)-2),CaseShiller30,5,0)*0.01,$K$3) -> 0.05 | L7: =$F7*$L$3 -> 84176 | M7: =$G7*$M$3 -> 286497 | N7: =AND(AF7<$AF$3,AG7<$AG$3) -> FALSE | O7: =AND(AP7<$AP$3,AQ7<$AQ$3) -> TRUE | P7: =AND(N7=FALSE,O7) -> TRUE | Q7: =AH7 -> 85949.1 | R7: =AU7 -> 0 | S7: =AR7 -> 0 | T7: =AZ7 -> 164974.59 | U7: =BA7 -> 19.194452 | V7: =AX7 -> 140002.03 | W7: =AY7 -> 1.6288946 | X7: =$X$3*M7 -> 8594.91 | Y7: =$Y$3 -> 0.0625 | Z7: =M7-X7 -> 277902.09 | AA7: =Z7*'PMI Rate Est'!$J$6/12 -> 270.95454 | AB7: ='Taxes & Ins by State'!B14*M7/12 -> 436.90792 | AC7: ='Taxes & Ins by State'!M4*M7/12 -> 188.75 | AD7: =MAX(J7*Y7/12,0) -> 0 | AE7: =-PMT(Y7/12,360,Z7) -> 1711.091 | AF7: =SUM(AE7,AC7,AB7,AA7)/(L7/12) -> 0.37175016 | AG7: =SUM(AE7,AC7,AB7,AA7,AD7)/(L7/12) -> 0.37175016 | AH7: =M7*$AH$3 -> 85949.1 | AI7: =Y7+$AI$3 -> 0.0625 | AJ7: =M7-X7-AH7 -> 191952.99 | AK7: =AH7*$AK$3/12 -> 0 | AL7: =AB7 -> 436.90792 | AM7: =AC7 -> 188.75 | AN7: =MAX(J7*Y7/12,0) -> 0 | AO7: =-PMT(AI7/12,360,AJ7) -> 1181.8876 | AP7: =SUM(AO7,AM7,AL7)/(L7/12) -> 0.25768088 | AQ7: =SUM(AO7,AM7,AL7,AK7,AN7)/(L7/12) -> 0.25768088 | AR7: =$AR$3*AK7*12 -> 0 | AS7: =$AS$3*(M7-X7) -> 5558.0418 | AT7: =$AT$3*(AH7) -> 2578.473 | AU7: =$AU$3*SUM(AR7,AS7,AT7) -> 0 | AV7: =AU7/M7 -> 0 | AW7: =POWER(1+K7,10)*M7 -> 466673.42 | AX7: =POWER(1+K7,10)*AH7 -> 140002.03 | AY7: =AX7/AH7 -> 1.6288946 | AZ7: =AW7-AX7-FV(AI7/12,(10*12),AO7,-AJ7) -> 164974.59 | BA7: =AZ7/X7 -> 19.194452 | BE7: =(L7/12)*35% -> 2455.1333 | BF7: =BE7-AC7-AB7-AA7 -> 1558.5209 | BG7: =$Y$3/12 -> 0.0052083333 | BH7: =(BG7*(1+BG7)^360) / (((1+BG7)^360)-1) -> 0.006157172 | BI7: =PV(BG7, 360, -BF7) -> 253122.84 | BK7: =BE7-AB7-AC7 -> 1829.4754 | BL7: =BK7/BH7 -> 297129.17 | BN7: =M7-BI7-X7 -> 24779.249 | BO7: =BN7/M7 -> 0.086490431 | BP7: =M7-BL7-X7 -> -19227.08 | BS7: =B7 -> Illinois | BT7: =L7 -> 84176 | BU7: =M7 -> 286497 | BV7: =H7 -> 1205 | BW7: =AA7 -> 270.95454 | BX7: =AB7 -> 436.90792 | BY7: =AC7 -> 188.75 | BZ7: =(BT7/12)*$BT$2 -> 2455.1333 | CA7: =BZ7-BW7-BX7-BY7 -> 1558.5209 | CB7: =6.25%/12 -> 0.0052083333 | CC7: =CE7/0.97 -> 260951.38 | CD7: =BU7-CC7 -> 25545.617 | CE7: =PV(CB7,360,-CA7) -> 253122.84 | CG7: =BZ7-BY7-BX7 -> 1829.4754 | CH7: =PV(CB7,360,-CG7) -> 297129.17 | CI7: =BU7*0.03 -> 8594.91 | CJ7: =BU7-CI7-CH7 -> -19227.08 | CK7: =CJ7/BU7 -> -0.06711093 | CM7: =CA7 -> 1558.5209 | CN7: =(CC7*1%)/12 -> 217.45949 | CO7: =CM7+CN7+BX7+BY7 -> 2401.6383 | CP7: =VLOOKUP(BS7,'Paste Snowflake Data Here'!$B$2:$K$21,10,FALSE) -> 1205 | CQ7: =CP7-CO7 -> -1196.6383
B8: Maryland | D8: =_xlfn.XLOOKUP($B8,'Paste Snowflake Data Here'!$B$3:$B$1048576,'Paste Snowflake Data Here'!$D$3:$D$1048576) -> 6270068 | F8: =_xlfn.XLOOKUP($B8,'Paste Snowflake Data Here'!$B$3:$B$1048576,'Paste Snowflake Data Here'!$I$3:$I$1048576) -> 103503 | G8: =_xlfn.XLOOKUP($B8,'Paste Snowflake Data Here'!$B$3:$B$1048576,'Paste Snowflake Data Here'!$J$3:$J$1048576) -> 468044 | H8: =_xlfn.XLOOKUP($B8,'Paste Snowflake Data Here'!$B$3:$B$1048576,'Paste Snowflake Data Here'!$K$3:$K$1048576) -> 1654 | K8: =IFERROR(VLOOKUP(LEFT(B8,FIND("County",B8)-2),CaseShiller30,5,0)*0.01,$K$3) -> 0.05 | L8: =$F8*$L$3 -> 103503 | M8: =$G8*$M$3 -> 468044 | N8: =AND(AF8<$AF$3,AG8<$AG$3) -> FALSE | O8: =AND(AP8<$AP$3,AQ8<$AQ$3) -> TRUE | P8: =AND(N8=FALSE,O8) -> TRUE | Q8: =AH8 -> 140413.2 | R8: =AU8 -> 0 | S8: =AR8 -> 0 | T8: =AZ8 -> 269515.44 | U8: =BA8 -> 19.194452 | V8: =AX8 -> 228718.31 | W8: =AY8 -> 1.6288946 | X8: =$X$3*M8 -> 14041.32 | Y8: =$Y$3 -> 0.0625 | Z8: =M8-X8 -> 454002.68 | AA8: =Z8*'PMI Rate Est'!$J$6/12 -> 442.65261 | AB8: ='Taxes & Ins by State'!B21*M8/12 -> 351.033 | AC8: ='Taxes & Ins by State'!M5*M8/12 -> 139.25 | AD8: =MAX(J8*Y8/12,0) -> 0 | AE8: =-PMT(Y8/12,360,Z8) -> 2795.3726 | AF8: =SUM(AE8,AC8,AB8,AA8)/(L8/12) -> 0.43225509 | AG8: =SUM(AE8,AC8,AB8,AA8,AD8)/(L8/12) -> 0.43225509 | AH8: =M8*$AH$3 -> 140413.2 | AI8: =Y8+$AI$3 -> 0.0625 | AJ8: =M8-X8-AH8 -> 313589.48 | AK8: =AH8*$AK$3/12 -> 0 | AL8: =AB8 -> 351.033 | AM8: =AC8 -> 139.25 | AN8: =MAX(J8*Y8/12,0) -> 0 | AO8: =-PMT(AI8/12,360,AJ8) -> 1930.8244 | AP8: =SUM(AO8,AM8,AL8)/(L8/12) -> 0.28069996 | AQ8: =SUM(AO8,AM8,AL8,AK8,AN8)/(L8/12) -> 0.28069996 | AR8: =$AR$3*AK8*12 -> 0 | AS8: =$AS$3*(M8-X8) -> 9080.0536 | AT8: =$AT$3*(AH8) -> 4212.396 | AU8: =$AU$3*SUM(AR8,AS8,AT8) -> 0 | AV8: =AU8/M8 -> 0 | AW8: =POWER(1+K8,10)*M8 -> 762394.36 | AX8: =POWER(1+K8,10)*AH8 -> 228718.31 | AY8: =AX8/AH8 -> 1.6288946 | AZ8: =AW8-AX8-FV(AI8/12,(10*12),AO8,-AJ8) -> 269515.44 | BA8: =AZ8/X8 -> 19.194452 | BE8: =(L8/12)*35% -> 3018.8375 | BF8: =BE8-AC8-AB8-AA8 -> 2085.9019 | BG8: =$Y$3/12 -> 0.0052083333 | BH8: =(BG8*(1+BG8)^360) / (((1+BG8)^360)-1) -> 0.006157172 | BI8: =PV(BG8, 360, -BF8) -> 338775.96 | BK8: =BE8-AB8-AC8 -> 2528.5545 | BL8: =BK8/BH8 -> 410668.16 | BN8: =M8-BI8-X8 -> 115226.72 | BO8: =BN8/M8 -> 0.24618778 | BP8: =M8-BL8-X8 -> 43334.52 | BS8: =B8 -> Maryland | BT8: =L8 -> 103503 | BU8: =M8 -> 468044 | BV8: =H8 -> 1654 | BW8: =AA8 -> 442.65261 | BX8: =AB8 -> 351.033 | BY8: =AC8 -> 139.25 | BZ8: =(BT8/12)*$BT$2 -> 3018.8375 | CA8: =BZ8-BW8-BX8-BY8 -> 2085.9019 | CB8: =6.25%/12 -> 0.0052083333 | CC8: =CE8/0.97 -> 349253.57 | CD8: =BU8-CC8 -> 118790.43 | CE8: =PV(CB8,360,-CA8) -> 338775.96 | CG8: =BZ8-BY8-BX8 -> 2528.5545 | CH8: =PV(CB8,360,-CG8) -> 410668.16 | CI8: =BU8*0.03 -> 14041.32 | CJ8: =BU8-CI8-CH8 -> 43334.52 | CK8: =CJ8/BU8 -> 0.092586423 | CM8: =CA8 -> 2085.9019 | CN8: =(CC8*1%)/12 -> 291.04464 | CO8: =CM8+CN8+BX8+BY8 -> 2867.2295 | CP8: =VLOOKUP(BS8,'Paste Snowflake Data Here'!$B$2:$K$21,10,FALSE) -> 1654 | CQ8: =CP8-CO8 -> -1213.2295
B9: Massachusetts | D9: =_xlfn.XLOOKUP($B9,'Paste Snowflake Data Here'!$B$3:$B$1048576,'Paste Snowflake Data Here'!$D$3:$D$1048576) -> 7069210 | F9: =_xlfn.XLOOKUP($B9,'Paste Snowflake Data Here'!$B$3:$B$1048576,'Paste Snowflake Data Here'!$I$3:$I$1048576) -> 105410 | G9: =_xlfn.XLOOKUP($B9,'Paste Snowflake Data Here'!$B$3:$B$1048576,'Paste Snowflake Data Here'!$J$3:$J$1048576) -> 637329 | H9: =_xlfn.XLOOKUP($B9,'Paste Snowflake Data Here'!$B$3:$B$1048576,'Paste Snowflake Data Here'!$K$3:$K$1048576) -> 1763 | K9: =IFERROR(VLOOKUP(LEFT(B9,FIND("County",B9)-2),CaseShiller30,5,0)*0.01,$K$3) -> 0.05 | L9: =$F9*$L$3 -> 105410 | M9: =$G9*$M$3 -> 637329 | N9: =AND(AF9<$AF$3,AG9<$AG$3) -> FALSE | O9: =AND(AP9<$AP$3,AQ9<$AQ$3) -> FALSE | P9: =AND(N9=FALSE,O9) -> FALSE | Q9: =AH9 -> 191198.7 | R9: =AU9 -> 0 | S9: =AR9 -> 0 | T9: =AZ9 -> 366995.43 | U9: =BA9 -> 19.194452 | V9: =AX9 -> 311442.54 | W9: =AY9 -> 1.6288946 | X9: =$X$3*M9 -> 19119.87 | Y9: =$Y$3 -> 0.0625 | Z9: =M9-X9 -> 618209.13 | AA9: =Z9*'PMI Rate Est'!$J$6/12 -> 602.7539 | AB9: ='Taxes & Ins by State'!B22*M9/12 -> 515.17427 | AC9: ='Taxes & Ins by State'!M6*M9/12 -> 141.91667 | AD9: =MAX(J9*Y9/12,0) -> 0 | AE9: =-PMT(Y9/12,360,Z9) -> 3806.4199 | AF9: =SUM(AE9,AC9,AB9,AA9)/(L9/12) -> 0.57674962 | AG9: =SUM(AE9,AC9,AB9,AA9,AD9)/(L9/12) -> 0.57674962 | AH9: =M9*$AH$3 -> 191198.7 | AI9: =Y9+$AI$3 -> 0.0625 | AJ9: =M9-X9-AH9 -> 427010.43 | AK9: =AH9*$AK$3/12 -> 0 | AL9: =AB9 -> 515.17427 | AM9: =AC9 -> 141.91667 | AN9: =MAX(J9*Y9/12,0) -> 0 | AO9: =-PMT(AI9/12,360,AJ9) -> 2629.1767 | AP9: =SUM(AO9,AM9,AL9)/(L9/12) -> 0.37411262 | AQ9: =SUM(AO9,AM9,AL9,AK9,AN9)/(L9/12) -> 0.37411262 | AR9: =$AR$3*AK9*12 -> 0 | AS9: =$AS$3*(M9-X9) -> 12364.183 | AT9: =$AT$3*(AH9) -> 5735.961 | AU9: =$AU$3*SUM(AR9,AS9,AT9) -> 0 | AV9: =AU9/M9 -> 0 | AW9: =POWER(1+K9,10)*M9 -> 1038141.8 | AX9: =POWER(1+K9,10)*AH9 -> 311442.54 | AY9: =AX9/AH9 -> 1.6288946 | AZ9: =AW9-AX9-FV(AI9/12,(10*12),AO9,-AJ9) -> 366995.43 | BA9: =AZ9/X9 -> 19.194452 | BE9: =(L9/12)*35% -> 3074.4583 | BF9: =BE9-AC9-AB9-AA9 -> 1814.6135 | BG9: =$Y$3/12 -> 0.0052083333 | BH9: =(BG9*(1+BG9)^360) / (((1+BG9)^360)-1) -> 0.006157172 | BI9: =PV(BG9, 360, -BF9) -> 294715.41 | BK9: =BE9-AB9-AC9 -> 2417.3674 | BL9: =BK9/BH9 -> 392610.01 | BN9: =M9-BI9-X9 -> 323493.72 | BO9: =BN9/M9 -> 0.50757727 | BP9: =M9-BL9-X9 -> 225599.12 | BS9: =B9 -> Massachusetts | BT9: =L9 -> 105410 | BU9: =M9 -> 637329 | BV9: =H9 -> 1763 | BW9: =AA9 -> 602.7539 | BX9: =AB9 -> 515.17427 | BY9: =AC9 -> 141.91667 | BZ9: =(BT9/12)*$BT$2 -> 3074.4583 | CA9: =BZ9-BW9-BX9-BY9 -> 1814.6135 | CB9: =6.25%/12 -> 0.0052083333 | CC9: =CE9/0.97 -> 303830.32 | CD9: =BU9-CC9 -> 333498.68 | CE9: =PV(CB9,360,-CA9) -> 294715.41 | CG9: =BZ9-BY9-BX9 -> 2417.3674 | CH9: =PV(CB9,360,-CG9) -> 392610.01 | CI9: =BU9*0.03 -> 19119.87 | CJ9: =BU9-CI9-CH9 -> 225599.12 | CK9: =CJ9/BU9 -> 0.35397591 | CM9: =CA9 -> 1814.6135 | CN9: =(CC9*1%)/12 -> 253.19194 | CO9: =CM9+CN9+BX9+BY9 -> 2724.8964 | CP9: =VLOOKUP(BS9,'Paste Snowflake Data Here'!$B$2:$K$21,10,FALSE) -> 1763 | CQ9: =CP9-CO9 -> -961.89637
B10: New Jersey | D10: =_xlfn.XLOOKUP($B10,'Paste Snowflake Data Here'!$B$3:$B$1048576,'Paste Snowflake Data Here'!$D$3:$D$1048576) -> 9425430 | F10: =_xlfn.XLOOKUP($B10,'Paste Snowflake Data Here'!$B$3:$B$1048576,'Paste Snowflake Data Here'!$I$3:$I$1048576) -> 104287 | G10: =_xlfn.XLOOKUP($B10,'Paste Snowflake Data Here'!$B$3:$B$1048576,'Paste Snowflake Data Here'!$J$3:$J$1048576) -> 513938 | H10: =_xlfn.XLOOKUP($B10,'Paste Snowflake Data Here'!$B$3:$B$1048576,'Paste Snowflake Data Here'!$K$3:$K$1048576) -> 1679 | K10: =IFERROR(VLOOKUP(LEFT(B10,FIND("County",B10)-2),CaseShiller30,5,0)*0.01,$K$3) -> 0.05 | L10: =$F10*$L$3 -> 104287 | M10: =$G10*$M$3 -> 513938 | N10: =AND(AF10<$AF$3,AG10<$AG$3) -> FALSE | O10: =AND(AP10<$AP$3,AQ10<$AQ$3) -> TRUE | P10: =AND(N10=FALSE,O10) -> TRUE | Q10: =AH10 -> 154181.4 | R10: =AU10 -> 0 | S10: =AR10 -> 0 | T10: =AZ10 -> 295942.75 | U10: =BA10 -> 19.194452 | V10: =AX10 -> 251145.25 | W10: =AY10 -> 1.6288946 | X10: =$X$3*M10 -> 15418.14 | Y10: =$Y$3 -> 0.0625 | Z10: =M10-X10 -> 498519.86 | AA10: =Z10*'PMI Rate Est'!$J$6/12 -> 486.05686 | AB10: ='Taxes & Ins by State'!B31*M10/12 -> 758.05855 | AC10: ='Taxes & Ins by State'!M7*M10/12 -> 99.5 | AD10: =MAX(J10*Y10/12,0) -> 0 | AE10: =-PMT(Y10/12,360,Z10) -> 3069.4725 | AF10: =SUM(AE10,AC10,AB10,AA10)/(L10/12) -> 0.50780112 | AG10: =SUM(AE10,AC10,AB10,AA10,AD10)/(L10/12) -> 0.50780112 | AH10: =M10*$AH$3 -> 154181.4 | AI10: =Y10+$AI$3 -> 0.0625 | AJ10: =M10-X10-AH10 -> 344338.46 | AK10: =AH10*$AK$3/12 -> 0 | AL10: =AB10 -> 758.05855 | AM10: =AC10 -> 99.5 | AN10: =MAX(J10*Y10/12,0) -> 0 | AO10: =-PMT(AI10/12,360,AJ10) -> 2120.1511 | AP10: =SUM(AO10,AM10,AL10)/(L10/12) -> 0.34263634 | AQ10: =SUM(AO10,AM10,AL10,AK10,AN10)/(L10/12) -> 0.34263634 | AR10: =$AR$3*AK10*12 -> 0 | AS10: =$AS$3*(M10-X10) -> 9970.3972 | AT10: =$AT$3*(AH10) -> 4625.442 | AU10: =$AU$3*SUM(AR10,AS10,AT10) -> 0 | AV10: =AU10/M10 -> 0 | AW10: =POWER(1+K10,10)*M10 -> 837150.85 | AX10: =POWER(1+K10,10)*AH10 -> 251145.25 | AY10: =AX10/AH10 -> 1.6288946 | AZ10: =AW10-AX10-FV(AI10/12,(10*12),AO10,-AJ10) -> 295942.75 | BA10: =AZ10/X10 -> 19.194452 | BE10: =(L10/12)*35% -> 3041.7042 | BF10: =BE10-AC10-AB10-AA10 -> 1698.0888 | BG10: =$Y$3/12 -> 0.0052083333 | BH10: =(BG10*(1+BG10)^360) / (((1+BG10)^360)-1) -> 0.006157172 | BI10: =PV(BG10, 360, -BF10) -> 275790.37 | BK10: =BE10-AB10-AC10 -> 2184.1456 | BL10: =BK10/BH10 -> 354731.95 | BN10: =M10-BI10-X10 -> 222729.49 | BO10: =BN10/M10 -> 0.43337813 | BP10: =M10-BL10-X10 -> 143787.91 | BS10: =B10 -> New Jersey | BT10: =L10 -> 104287 | BU10: =M10 -> 513938 | BV10: =H10 -> 1679 | BW10: =AA10 -> 486.05686 | BX10: =AB10 -> 758.05855 | BY10: =AC10 -> 99.5 | BZ10: =(BT10/12)*$BT$2 -> 3041.7042 | CA10: =BZ10-BW10-BX10-BY10 -> 1698.0888 | CB10: =6.25%/12 -> 0.0052083333 | CC10: =CE10/0.97 -> 284319.97 | CD10: =BU10-CC10 -> 229618.03 | CE10: =PV(CB10,360,-CA10) -> 275790.37 | CG10: =BZ10-BY10-BX10 -> 2184.1456 | CH10: =PV(CB10,360,-CG10) -> 354731.95 | CI10: =BU10*0.03 -> 15418.14 | CJ10: =BU10-CI10-CH10 -> 143787.91 | CK10: =CJ10/BU10 -> 0.27977677 | CM10: =CA10 -> 1698.0888 | CN10: =(CC10*1%)/12 -> 236.93331 | CO10: =CM10+CN10+BX10+BY10 -> 2792.5806 | CP10: =VLOOKUP(BS10,'Paste Snowflake Data Here'!$B$2:$K$21,10,FALSE) -> 1679 | CQ10: =CP10-CO10 -> -1113.5806
B11: New York | D11: =_xlfn.XLOOKUP($B11,'Paste Snowflake Data Here'!$B$3:$B$1048576,'Paste Snowflake Data Here'!$D$3:$D$1048576) -> 19998175 | F11: =_xlfn.XLOOKUP($B11,'Paste Snowflake Data Here'!$B$3:$B$1048576,'Paste Snowflake Data Here'!$I$3:$I$1048576) -> 85744 | G11: =_xlfn.XLOOKUP($B11,'Paste Snowflake Data Here'!$B$3:$B$1048576,'Paste Snowflake Data Here'!$J$3:$J$1048576) -> 485429 | H11: =_xlfn.XLOOKUP($B11,'Paste Snowflake Data Here'!$B$3:$B$1048576,'Paste Snowflake Data Here'!$K$3:$K$1048576) -> 1617 | K11: =IFERROR(VLOOKUP(LEFT(B11,FIND("County",B11)-2),CaseShiller30,5,0)*0.01,$K$3) -> 0.05 | L11: =$F11*$L$3 -> 85744 | M11: =$G11*$M$3 -> 485429 | N11: =AND(AF11<$AF$3,AG11<$AG$3) -> FALSE | O11: =AND(AP11<$AP$3,AQ11<$AQ$3) -> FALSE | P11: =AND(N11=FALSE,O11) -> FALSE | Q11: =AH11 -> 145628.7 | R11: =AU11 -> 0 | S11: =AR11 -> 0 | T11: =AZ11 -> 279526.31 | U11: =BA11 -> 19.194452 | V11: =AX11 -> 237213.81 | W11: =AY11 -> 1.6288946 | X11: =$X$3*M11 -> 14562.87 | Y11: =$Y$3 -> 0.0625 | Z11: =M11-X11 -> 470866.13 | AA11: =Z11*'PMI Rate Est'!$J$6/12 -> 459.09448 | AB11: ='Taxes & Ins by State'!B33*M11/12 -> 509.70045 | AC11: ='Taxes & Ins by State'!M8*M11/12 -> 146 | AD11: =MAX(J11*Y11/12,0) -> 0 | AE11: =-PMT(Y11/12,360,Z11) -> 2899.2038 | AF11: =SUM(AE11,AC11,AB11,AA11)/(L11/12) -> 0.56176507 | AG11: =SUM(AE11,AC11,AB11,AA11,AD11)/(L11/12) -> 0.56176507 | AH11: =M11*$AH$3 -> 145628.7 | AI11: =Y11+$AI$3 -> 0.0625 | AJ11: =M11-X11-AH11 -> 325237.43 | AK11: =AH11*$AK$3/12 -> 0 | AL11: =AB11 -> 509.70045 | AM11: =AC11 -> 146 | AN11: =MAX(J11*Y11/12,0) -> 0 | AO11: =-PMT(AI11/12,360,AJ11) -> 2002.5428 | AP11: =SUM(AO11,AM11,AL11)/(L11/12) -> 0.37202509 | AQ11: =SUM(AO11,AM11,AL11,AK11,AN11)/(L11/12) -> 0.37202509 | AR11: =$AR$3*AK11*12 -> 0 | AS11: =$AS$3*(M11-X11) -> 9417.3226 | AT11: =$AT$3*(AH11) -> 4368.861 | AU11: =$AU$3*SUM(AR11,AS11,AT11) -> 0 | AV11: =AU11/M11 -> 0 | AW11: =POWER(1+K11,10)*M11 -> 790712.69 | AX11: =POWER(1+K11,10)*AH11 -> 237213.81 | AY11: =AX11/AH11 -> 1.6288946 | AZ11: =AW11-AX11-FV(AI11/12,(10*12),AO11,-AJ11) -> 279526.31 | BA11: =AZ11/X11 -> 19.194452 | BE11: =(L11/12)*35% -> 2500.8667 | BF11: =BE11-AC11-AB11-AA11 -> 1386.0717 | BG11: =$Y$3/12 -> 0.0052083333 | BH11: =(BG11*(1+BG11)^360) / (((1+BG11)^360)-1) -> 0.006157172 | BI11: =PV(BG11, 360, -BF11) -> 225114.99 | BK11: =BE11-AB11-AC11 -> 1845.1662 | BL11: =BK11/BH11 -> 299677.55 | BN11: =M11-BI11-X11 -> 245751.14 | BO11: =BN11/M11 -> 0.50625557 | BP11: =M11-BL11-X11 -> 171188.58 | BS11: =B11 -> New York | BT11: =L11 -> 85744 | BU11: =M11 -> 485429 | BV11: =H11 -> 1617 | BW11: =AA11 -> 459.09448 | BX11: =AB11 -> 509.70045 | BY11: =AC11 -> 146 | BZ11: =(BT11/12)*$BT$2 -> 2500.8667 | CA11: =BZ11-BW11-BX11-BY11 -> 1386.0717 | CB11: =6.25%/12 -> 0.0052083333 | CC11: =CE11/0.97 -> 232077.31 | CD11: =BU11-CC11 -> 253351.69 | CE11: =PV(CB11,360,-CA11) -> 225114.99 | CG11: =BZ11-BY11-BX11 -> 1845.1662 | CH11: =PV(CB11,360,-CG11) -> 299677.55 | CI11: =BU11*0.03 -> 14562.87 | CJ11: =BU11-CI11-CH11 -> 171188.58 | CK11: =CJ11/BU11 -> 0.35265421 | CM11: =CA11 -> 1386.0717 | CN11: =(CC11*1%)/12 -> 193.39776 | CO11: =CM11+CN11+BX11+BY11 -> 2235.17 | CP11: =VLOOKUP(BS11,'Paste Snowflake Data Here'!$B$2:$K$21,10,FALSE) -> 1617 | CQ11: =CP11-CO11 -> -618.16995
B12: North Carolina | D12: =_xlfn.XLOOKUP($B12,'Paste Snowflake Data Here'!$B$3:$B$1048576,'Paste Snowflake Data Here'!$D$3:$D$1048576) -> 10995758 | F12: =_xlfn.XLOOKUP($B12,'Paste Snowflake Data Here'!$B$3:$B$1048576,'Paste Snowflake Data Here'!$I$3:$I$1048576) -> 74690 | G12: =_xlfn.XLOOKUP($B12,'Paste Snowflake Data Here'!$B$3:$B$1048576,'Paste Snowflake Data Here'!$J$3:$J$1048576) -> 334561 | H12: =_xlfn.XLOOKUP($B12,'Paste Snowflake Data Here'!$B$3:$B$1048576,'Paste Snowflake Data Here'!$K$3:$K$1048576) -> 1180 | K12: =IFERROR(VLOOKUP(LEFT(B12,FIND("County",B12)-2),CaseShiller30,5,0)*0.01,$K$3) -> 0.05 | L12: =$F12*$L$3 -> 74690 | M12: =$G12*$M$3 -> 334561 | N12: =AND(AF12<$AF$3,AG12<$AG$3) -> FALSE | O12: =AND(AP12<$AP$3,AQ12<$AQ$3) -> TRUE | P12: =AND(N12=FALSE,O12) -> TRUE | Q12: =AH12 -> 100368.3 | R12: =AU12 -> 0 | S12: =AR12 -> 0 | T12: =AZ12 -> 192651.45 | U12: =BA12 -> 19.194452 | V12: =AX12 -> 163489.38 | W12: =AY12 -> 1.6288946 | X12: =$X$3*M12 -> 10036.83 | Y12: =$Y$3 -> 0.0625 | Z12: =M12-X12 -> 324524.17 | AA12: =Z12*'PMI Rate Est'!$J$6/12 -> 316.41107 | AB12: ='Taxes & Ins by State'!B34*M12/12 -> 172.85652 | AC12: ='Taxes & Ins by State'!M9*M12/12 -> 171.25 | AD12: =MAX(J12*Y12/12,0) -> 0 | AE12: =-PMT(Y12/12,360,Z12) -> 1998.1511 | AF12: =SUM(AE12,AC12,AB12,AA12)/(L12/12) -> 0.42715256 | AG12: =SUM(AE12,AC12,AB12,AA12,AD12)/(L12/12) -> 0.42715256 | AH12: =M12*$AH$3 -> 100368.3 | AI12: =Y12+$AI$3 -> 0.0625 | AJ12: =M12-X12-AH12 -> 224155.87 | AK12: =AH12*$AK$3/12 -> 0 | AL12: =AB12 -> 172.85652 | AM12: =AC12 -> 171.25 | AN12: =MAX(J12*Y12/12,0) -> 0 | AO12: =-PMT(AI12/12,360,AJ12) -> 1380.1662 | AP12: =SUM(AO12,AM12,AL12)/(L12/12) -> 0.27702869 | AQ12: =SUM(AO12,AM12,AL12,AK12,AN12)/(L12/12) -> 0.27702869 | AR12: =$AR$3*AK12*12 -> 0 | AS12: =$AS$3*(M12-X12) -> 6490.4834 | AT12: =$AT$3*(AH12) -> 3011.049 | AU12: =$AU$3*SUM(AR12,AS12,AT12) -> 0 | AV12: =AU12/M12 -> 0 | AW12: =POWER(1+K12,10)*M12 -> 544964.62 | AX12: =POWER(1+K12,10)*AH12 -> 163489.38 | AY12: =AX12/AH12 -> 1.6288946 | AZ12: =AW12-AX12-FV(AI12/12,(10*12),AO12,-AJ12) -> 192651.45 | BA12: =AZ12/X12 -> 19.194452 | BE12: =(L12/12)*35% -> 2178.4583 | BF12: =BE12-AC12-AB12-AA12 -> 1517.9408 | BG12: =$Y$3/12 -> 0.0052083333 | BH12: =(BG12*(1+BG12)^360) / (((1+BG12)^360)-1) -> 0.006157172 | BI12: =PV(BG12, 360, -BF12) -> 246532.13 | BK12: =BE12-AB12-AC12 -> 1834.3518 | BL12: =BK12/BH12 -> 297921.16 | BN12: =M12-BI12-X12 -> 77992.036 | BO12: =BN12/M12 -> 0.23311754 | BP12: =M12-BL12-X12 -> 26603.011 | BS12: =B12 -> North Carolina | BT12: =L12 -> 74690 | BU12: =M12 -> 334561 | BV12: =H12 -> 1180 | BW12: =AA12 -> 316.41107 | BX12: =AB12 -> 172.85652 | BY12: =AC12 -> 171.25 | BZ12: =(BT12/12)*$BT$2 -> 2178.4583 | CA12: =BZ12-BW12-BX12-BY12 -> 1517.9408 | CB12: =6.25%/12 -> 0.0052083333 | CC12: =CE12/0.97 -> 254156.84 | CD12: =BU12-CC12 -> 80404.161 | CE12: =PV(CB12,360,-CA12) -> 246532.13 | CG12: =BZ12-BY12-BX12 -> 1834.3518 | CH12: =PV(CB12,360,-CG12) -> 297921.16 | CI12: =BU12*0.03 -> 10036.83 | CJ12: =BU12-CI12-CH12 -> 26603.011 | CK12: =CJ12/BU12 -> 0.079516176 | CM12: =CA12 -> 1517.9408 | CN12: =(CC12*1%)/12 -> 211.79737 | CO12: =CM12+CN12+BX12+BY12 -> 2073.8446 | CP12: =VLOOKUP(BS12,'Paste Snowflake Data Here'!$B$2:$K$21,10,FALSE) -> 1180 | CQ12: =CP12-CO12 -> -893.84463
B13: Oregon | D13: =_xlfn.XLOOKUP($B13,'Paste Snowflake Data Here'!$B$3:$B$1048576,'Paste Snowflake Data Here'!$D$3:$D$1048576) -> 4365325 | F13: =_xlfn.XLOOKUP($B13,'Paste Snowflake Data Here'!$B$3:$B$1048576,'Paste Snowflake Data Here'!$I$3:$I$1048576) -> 84398 | G13: =_xlfn.XLOOKUP($B13,'Paste Snowflake Data Here'!$B$3:$B$1048576,'Paste Snowflake Data Here'!$J$3:$J$1048576) -> 549301 | H13: =_xlfn.XLOOKUP($B13,'Paste Snowflake Data Here'!$B$3:$B$1048576,'Paste Snowflake Data Here'!$K$3:$K$1048576) -> 1477 | K13: =IFERROR(VLOOKUP(LEFT(B13,FIND("County",B13)-2),CaseShiller30,5,0)*0.01,$K$3) -> 0.05 | L13: =$F13*$L$3 -> 84398 | M13: =$G13*$M$3 -> 549301 | N13: =AND(AF13<$AF$3,AG13<$AG$3) -> FALSE | O13: =AND(AP13<$AP$3,AQ13<$AQ$3) -> FALSE | P13: =AND(N13=FALSE,O13) -> FALSE | Q13: =AH13 -> 164790.3 | R13: =AU13 -> 0 | S13: =AR13 -> 0 | T13: =AZ13 -> 316305.95 | U13: =BA13 -> 19.194452 | V13: =AX13 -> 268426.03 | W13: =AY13 -> 1.6288946 | X13: =$X$3*M13 -> 16479.03 | Y13: =$Y$3 -> 0.0625 | Z13: =M13-X13 -> 532821.97 | AA13: =Z13*'PMI Rate Est'!$J$6/12 -> 519.50142 | AB13: ='Taxes & Ins by State'!B38*M13/12 -> 357.04565 | AC13: ='Taxes & Ins by State'!M10*M13/12 -> 84.25 | AD13: =MAX(J13*Y13/12,0) -> 0 | AE13: =-PMT(Y13/12,360,Z13) -> 3280.6765 | AF13: =SUM(AE13,AC13,AB13,AA13)/(L13/12) -> 0.60306741 | AG13: =SUM(AE13,AC13,AB13,AA13,AD13)/(L13/12) -> 0.60306741 | AH13: =M13*$AH$3 -> 164790.3 | AI13: =Y13+$AI$3 -> 0.0625 | AJ13: =M13-X13-AH13 -> 368031.67 | AK13: =AH13*$AK$3/12 -> 0 | AL13: =AB13 -> 357.04565 | AM13: =AC13 -> 84.25 | AN13: =MAX(J13*Y13/12,0) -> 0 | AO13: =-PMT(AI13/12,360,AJ13) -> 2266.0343 | AP13: =SUM(AO13,AM13,AL13)/(L13/12) -> 0.38493755 | AQ13: =SUM(AO13,AM13,AL13,AK13,AN13)/(L13/12) -> 0.38493755 | AR13: =$AR$3*AK13*12 -> 0 | AS13: =$AS$3*(M13-X13) -> 10656.439 | AT13: =$AT$3*(AH13) -> 4943.709 | AU13: =$AU$3*SUM(AR13,AS13,AT13) -> 0 | AV13: =AU13/M13 -> 0 | AW13: =POWER(1+K13,10)*M13 -> 894753.45 | AX13: =POWER(1+K13,10)*AH13 -> 268426.03 | AY13: =AX13/AH13 -> 1.6288946 | AZ13: =AW13-AX13-FV(AI13/12,(10*12),AO13,-AJ13) -> 316305.95 | BA13: =AZ13/X13 -> 19.194452 | BE13: =(L13/12)*35% -> 2461.6083 | BF13: =BE13-AC13-AB13-AA13 -> 1500.8113 | BG13: =$Y$3/12 -> 0.0052083333 | BH13: =(BG13*(1+BG13)^360) / (((1+BG13)^360)-1) -> 0.006157172 | BI13: =PV(BG13, 360, -BF13) -> 243750.1 | BK13: =BE13-AB13-AC13 -> 2020.3127 | BL13: =BK13/BH13 -> 328123.48 | BN13: =M13-BI13-X13 -> 289071.87 | BO13: =BN13/M13 -> 0.52625405 | BP13: =M13-BL13-X13 -> 204698.49 | BS13: =B13 -> Oregon | BT13: =L13 -> 84398 | BU13: =M13 -> 549301 | BV13: =H13 -> 1477 | BW13: =AA13 -> 519.50142 | BX13: =AB13 -> 357.04565 | BY13: =AC13 -> 84.25 | BZ13: =(BT13/12)*$BT$2 -> 2461.6083 | CA13: =BZ13-BW13-BX13-BY13 -> 1500.8113 | CB13: =6.25%/12 -> 0.0052083333 | CC13: =CE13/0.97 -> 251288.76 | CD13: =BU13-CC13 -> 298012.24 | CE13: =PV(CB13,360,-CA13) -> 243750.1 | CG13: =BZ13-BY13-BX13 -> 2020.3127 | CH13: =PV(CB13,360,-CG13) -> 328123.48 | CI13: =BU13*0.03 -> 16479.03 | CJ13: =BU13-CI13-CH13 -> 204698.49 | CK13: =CJ13/BU13 -> 0.37265269 | CM13: =CA13 -> 1500.8113 | CN13: =(CC13*1%)/12 -> 209.4073 | CO13: =CM13+CN13+BX13+BY13 -> 2151.5142 | CP13: =VLOOKUP(BS13,'Paste Snowflake Data Here'!$B$2:$K$21,10,FALSE) -> 1477 | CQ13: =CP13-CO13 -> -674.51421
B14: Pennsylvania | D14: =_xlfn.XLOOKUP($B14,'Paste Snowflake Data Here'!$B$3:$B$1048576,'Paste Snowflake Data Here'!$D$3:$D$1048576) -> 13074028 | F14: =_xlfn.XLOOKUP($B14,'Paste Snowflake Data Here'!$B$3:$B$1048576,'Paste Snowflake Data Here'!$I$3:$I$1048576) -> 77579 | G14: =_xlfn.XLOOKUP($B14,'Paste Snowflake Data Here'!$B$3:$B$1048576,'Paste Snowflake Data Here'!$J$3:$J$1048576) -> 303362 | H14: =_xlfn.XLOOKUP($B14,'Paste Snowflake Data Here'!$B$3:$B$1048576,'Paste Snowflake Data Here'!$K$3:$K$1048576) -> 1159 | K14: =IFERROR(VLOOKUP(LEFT(B14,FIND("County",B14)-2),CaseShiller30,5,0)*0.01,$K$3) -> 0.05 | L14: =$F14*$L$3 -> 77579 | M14: =$G14*$M$3 -> 303362 | N14: =AND(AF14<$AF$3,AG14<$AG$3) -> FALSE | O14: =AND(AP14<$AP$3,AQ14<$AQ$3) -> TRUE | P14: =AND(N14=FALSE,O14) -> TRUE | Q14: =AH14 -> 91008.6 | R14: =AU14 -> 0 | S14: =AR14 -> 0 | T14: =AZ14 -> 174686.02 | U14: =BA14 -> 19.194452 | V14: =AX14 -> 148243.42 | W14: =AY14 -> 1.6288946 | X14: =$X$3*M14 -> 9100.86 | Y14: =$Y$3 -> 0.0625 | Z14: =M14-X14 -> 294261.14 | AA14: =Z14*'PMI Rate Est'!$J$6/12 -> 286.90461 | AB14: ='Taxes & Ins by State'!B39*M14/12 -> 300.83398 | AC14: ='Taxes & Ins by State'!M11*M14/12 -> 103.75 | AD14: =MAX(J14*Y14/12,0) -> 0 | AE14: =-PMT(Y14/12,360,Z14) -> 1811.8165 | AF14: =SUM(AE14,AC14,AB14,AA14)/(L14/12) -> 0.38721382 | AG14: =SUM(AE14,AC14,AB14,AA14,AD14)/(L14/12) -> 0.38721382 | AH14: =M14*$AH$3 -> 91008.6 | AI14: =Y14+$AI$3 -> 0.0625 | AJ14: =M14-X14-AH14 -> 203252.54 | AK14: =AH14*$AK$3/12 -> 0 | AL14: =AB14 -> 300.83398 | AM14: =AC14 -> 103.75 | AN14: =MAX(J14*Y14/12,0) -> 0 | AO14: =-PMT(AI14/12,360,AJ14) -> 1251.4608 | AP14: =SUM(AO14,AM14,AL14)/(L14/12) -> 0.25615873 | AQ14: =SUM(AO14,AM14,AL14,AK14,AN14)/(L14/12) -> 0.25615873 | AR14: =$AR$3*AK14*12 -> 0 | AS14: =$AS$3*(M14-X14) -> 5885.2228 | AT14: =$AT$3*(AH14) -> 2730.258 | AU14: =$AU$3*SUM(AR14,AS14,AT14) -> 0 | AV14: =AU14/M14 -> 0 | AW14: =POWER(1+K14,10)*M14 -> 494144.73 | AX14: =POWER(1+K14,10)*AH14 -> 148243.42 | AY14: =AX14/AH14 -> 1.6288946 | AZ14: =AW14-AX14-FV(AI14/12,(10*12),AO14,-AJ14) -> 174686.02 | BA14: =AZ14/X14 -> 19.194452 | BE14: =(L14/12)*35% -> 2262.7208 | BF14: =BE14-AC14-AB14-AA14 -> 1571.2322 | BG14: =$Y$3/12 -> 0.0052083333 | BH14: =(BG14*(1+BG14)^360) / (((1+BG14)^360)-1) -> 0.006157172 | BI14: =PV(BG14, 360, -BF14) -> 255187.32 | BK14: =BE14-AB14-AC14 -> 1858.1368 | BL14: =BK14/BH14 -> 301784.14 | BN14: =M14-BI14-X14 -> 39073.817 | BO14: =BN14/M14 -> 0.12880261 | BP14: =M14-BL14-X14 -> -7522.9987 | BS14: =B14 -> Pennsylvania | BT14: =L14 -> 77579 | BU14: =M14 -> 303362 | BV14: =H14 -> 1159 | BW14: =AA14 -> 286.90461 | BX14: =AB14 -> 300.83398 | BY14: =AC14 -> 103.75 | BZ14: =(BT14/12)*$BT$2 -> 2262.7208 | CA14: =BZ14-BW14-BX14-BY14 -> 1571.2322 | CB14: =6.25%/12 -> 0.0052083333 | CC14: =CE14/0.97 -> 263079.71 | CD14: =BU14-CC14 -> 40282.286 | CE14: =PV(CB14,360,-CA14) -> 255187.32 | CG14: =BZ14-BY14-BX14 -> 1858.1368 | CH14: =PV(CB14,360,-CG14) -> 301784.14 | CI14: =BU14*0.03 -> 9100.86 | CJ14: =BU14-CI14-CH14 -> -7522.9987 | CK14: =CJ14/BU14 -> -0.024798751 | CM14: =CA14 -> 1571.2322 | CN14: =(CC14*1%)/12 -> 219.2331 | CO14: =CM14+CN14+BX14+BY14 -> 2195.0493 | CP14: =VLOOKUP(BS14,'Paste Snowflake Data Here'!$B$2:$K$21,10,FALSE) -> 1159 | CQ14: =CP14-CO14 -> -1036.0493
B15: Rhode Island | D15: =_xlfn.XLOOKUP($B15,'Paste Snowflake Data Here'!$B$3:$B$1048576,'Paste Snowflake Data Here'!$D$3:$D$1048576) -> 1101918 | F15: =_xlfn.XLOOKUP($B15,'Paste Snowflake Data Here'!$B$3:$B$1048576,'Paste Snowflake Data Here'!$I$3:$I$1048576) -> 88514 | G15: =_xlfn.XLOOKUP($B15,'Paste Snowflake Data Here'!$B$3:$B$1048576,'Paste Snowflake Data Here'!$J$3:$J$1048576) -> 447602 | H15: =_xlfn.XLOOKUP($B15,'Paste Snowflake Data Here'!$B$3:$B$1048576,'Paste Snowflake Data Here'!$K$3:$K$1048576) -> 1303 | K15: =IFERROR(VLOOKUP(LEFT(B15,FIND("County",B15)-2),CaseShiller30,5,0)*0.01,$K$3) -> 0.05 | L15: =$F15*$L$3 -> 88514 | M15: =$G15*$M$3 -> 447602 | N15: =AND(AF15<$AF$3,AG15<$AG$3) -> FALSE | O15: =AND(AP15<$AP$3,AQ15<$AQ$3) -> TRUE | P15: =AND(N15=FALSE,O15) -> TRUE | Q15: =AH15 -> 134280.6 | R15: =AU15 -> 0 | S15: =AR15 -> 0 | T15: =AZ15 -> 257744.25 | U15: =BA15 -> 19.194452 | V15: =AX15 -> 218728.95 | W15: =AY15 -> 1.6288946 | X15: =$X$3*M15 -> 13428.06 | Y15: =$Y$3 -> 0.0625 | Z15: =M15-X15 -> 434173.94 | AA15: =Z15*'PMI Rate Est'!$J$6/12 -> 423.31959 | AB15: ='Taxes & Ins by State'!B40*M15/12 -> 391.65175 | AC15: ='Taxes & Ins by State'!M12*M15/12 -> 193.66667 | AD15: =MAX(J15*Y15/12,0) -> 0 | AE15: =-PMT(Y15/12,360,Z15) -> 2673.2836 | AF15: =SUM(AE15,AC15,AB15,AA15)/(L15/12) -> 0.49916465 | AG15: =SUM(AE15,AC15,AB15,AA15,AD15)/(L15/12) -> 0.49916465 | AH15: =M15*$AH$3 -> 134280.6 | AI15: =Y15+$AI$3 -> 0.0625 | AJ15: =M15-X15-AH15 -> 299893.34 | AK15: =AH15*$AK$3/12 -> 0 | AL15: =AB15 -> 391.65175 | AM15: =AC15 -> 193.66667 | AN15: =MAX(J15*Y15/12,0) -> 0 | AO15: =-PMT(AI15/12,360,AJ15) -> 1846.4949 | AP15: =SUM(AO15,AM15,AL15)/(L15/12) -> 0.32968524 | AQ15: =SUM(AO15,AM15,AL15,AK15,AN15)/(L15/12) -> 0.32968524 | AR15: =$AR$3*AK15*12 -> 0 | AS15: =$AS$3*(M15-X15) -> 8683.4788 | AT15: =$AT$3*(AH15) -> 4028.418 | AU15: =$AU$3*SUM(AR15,AS15,AT15) -> 0 | AV15: =AU15/M15 -> 0 | AW15: =POWER(1+K15,10)*M15 -> 729096.49 | AX15: =POWER(1+K15,10)*AH15 -> 218728.95 | AY15: =AX15/AH15 -> 1.6288946 | AZ15: =AW15-AX15-FV(AI15/12,(10*12),AO15,-AJ15) -> 257744.25 | BA15: =AZ15/X15 -> 19.194452 | BE15: =(L15/12)*35% -> 2581.6583 | BF15: =BE15-AC15-AB15-AA15 -> 1573.0203 | BG15: =$Y$3/12 -> 0.0052083333 | BH15: =(BG15*(1+BG15)^360) / (((1+BG15)^360)-1) -> 0.006157172 | BI15: =PV(BG15, 360, -BF15) -> 255477.73 | BK15: =BE15-AB15-AC15 -> 1996.3399 | BL15: =BK15/BH15 -> 324230.01 | BN15: =M15-BI15-X15 -> 178696.21 | BO15: =BN15/M15 -> 0.39923014 | BP15: =M15-BL15-X15 -> 109943.93 | BS15: =B15 -> Rhode Island | BT15: =L15 -> 88514 | BU15: =M15 -> 447602 | BV15: =H15 -> 1303 | BW15: =AA15 -> 423.31959 | BX15: =AB15 -> 391.65175 | BY15: =AC15 -> 193.66667 | BZ15: =(BT15/12)*$BT$2 -> 2581.6583 | CA15: =BZ15-BW15-BX15-BY15 -> 1573.0203 | CB15: =6.25%/12 -> 0.0052083333 | CC15: =CE15/0.97 -> 263379.1 | CD15: =BU15-CC15 -> 184222.9 | CE15: =PV(CB15,360,-CA15) -> 255477.73 | CG15: =BZ15-BY15-BX15 -> 1996.3399 | CH15: =PV(CB15,360,-CG15) -> 324230.01 | CI15: =BU15*0.03 -> 13428.06 | CJ15: =BU15-CI15-CH15 -> 109943.93 | CK15: =CJ15/BU15 -> 0.24562878 | CM15: =CA15 -> 1573.0203 | CN15: =(CC15*1%)/12 -> 219.48259 | CO15: =CM15+CN15+BX15+BY15 -> 2377.8213 | CP15: =VLOOKUP(BS15,'Paste Snowflake Data Here'!$B$2:$K$21,10,FALSE) -> 1303 | CQ15: =CP15-CO15 -> -1074.8213
B16: Washington | D16: =_xlfn.XLOOKUP($B16,'Paste Snowflake Data Here'!$B$3:$B$1048576,'Paste Snowflake Data Here'!$D$3:$D$1048576) -> 8076991 | F16: =_xlfn.XLOOKUP($B16,'Paste Snowflake Data Here'!$B$3:$B$1048576,'Paste Snowflake Data Here'!$I$3:$I$1048576) -> 100361 | G16: =_xlfn.XLOOKUP($B16,'Paste Snowflake Data Here'!$B$3:$B$1048576,'Paste Snowflake Data Here'!$J$3:$J$1048576) -> 641336 | H16: =_xlfn.XLOOKUP($B16,'Paste Snowflake Data Here'!$B$3:$B$1048576,'Paste Snowflake Data Here'!$K$3:$K$1048576) -> 1701 | K16: =IFERROR(VLOOKUP(LEFT(B16,FIND("County",B16)-2),CaseShiller30,5,0)*0.01,$K$3) -> 0.05 | L16: =$F16*$L$3 -> 100361 | M16: =$G16*$M$3 -> 641336 | N16: =AND(AF16<$AF$3,AG16<$AG$3) -> FALSE | O16: =AND(AP16<$AP$3,AQ16<$AQ$3) -> FALSE | P16: =AND(N16=FALSE,O16) -> FALSE | Q16: =AH16 -> 192400.8 | R16: =AU16 -> 0 | S16: =AR16 -> 0 | T16: =AZ16 -> 369302.79 | U16: =BA16 -> 19.194452 | V16: =AX16 -> 313400.63 | W16: =AY16 -> 1.6288946 | X16: =$X$3*M16 -> 19240.08 | Y16: =$Y$3 -> 0.0625 | Z16: =M16-X16 -> 622095.92 | AA16: =Z16*'PMI Rate Est'!$J$6/12 -> 606.54352 | AB16: ='Taxes & Ins by State'!B48*M16/12 -> 400.835 | AC16: ='Taxes & Ins by State'!M13*M16/12 -> 126.08333 | AD16: =MAX(J16*Y16/12,0) -> 0 | AE16: =-PMT(Y16/12,360,Z16) -> 3830.3516 | AF16: =SUM(AE16,AC16,AB16,AA16)/(L16/12) -> 0.59351502 | AG16: =SUM(AE16,AC16,AB16,AA16,AD16)/(L16/12) -> 0.59351502 | AH16: =M16*$AH$3 -> 192400.8 | AI16: =Y16+$AI$3 -> 0.0625 | AJ16: =M16-X16-AH16 -> 429695.12 | AK16: =AH16*$AK$3/12 -> 0 | AL16: =AB16 -> 400.835 | AM16: =AC16 -> 126.08333 | AN16: =MAX(J16*Y16/12,0) -> 0 | AO16: =-PMT(AI16/12,360,AJ16) -> 2645.7068 | AP16: =SUM(AO16,AM16,AL16)/(L16/12) -> 0.37934557 | AQ16: =SUM(AO16,AM16,AL16,AK16,AN16)/(L16/12) -> 0.37934557 | AR16: =$AR$3*AK16*12 -> 0 | AS16: =$AS$3*(M16-X16) -> 12441.918 | AT16: =$AT$3*(AH16) -> 5772.024 | AU16: =$AU$3*SUM(AR16,AS16,AT16) -> 0 | AV16: =AU16/M16 -> 0 | AW16: =POWER(1+K16,10)*M16 -> 1044668.8 | AX16: =POWER(1+K16,10)*AH16 -> 313400.63 | AY16: =AX16/AH16 -> 1.6288946 | AZ16: =AW16-AX16-FV(AI16/12,(10*12),AO16,-AJ16) -> 369302.79 | BA16: =AZ16/X16 -> 19.194452 | BE16: =(L16/12)*35% -> 2927.1958 | BF16: =BE16-AC16-AB16-AA16 -> 1793.734 | BG16: =$Y$3/12 -> 0.0052083333 | BH16: =(BG16*(1+BG16)^360) / (((1+BG16)^360)-1) -> 0.006157172 | BI16: =PV(BG16, 360, -BF16) -> 291324.32 | BK16: =BE16-AB16-AC16 -> 2400.2775 | BL16: =BK16/BH16 -> 389834.41 | BN16: =M16-BI16-X16 -> 330771.6 | BO16: =BN16/M16 -> 0.51575398 | BP16: =M16-BL16-X16 -> 232261.51 | BS16: =B16 -> Washington | BT16: =L16 -> 100361 | BU16: =M16 -> 641336 | BV16: =H16 -> 1701 | BW16: =AA16 -> 606.54352 | BX16: =AB16 -> 400.835 | BY16: =AC16 -> 126.08333 | BZ16: =(BT16/12)*$BT$2 -> 2927.1958 | CA16: =BZ16-BW16-BX16-BY16 -> 1793.734 | CB16: =6.25%/12 -> 0.0052083333 | CC16: =CE16/0.97 -> 300334.36 | CD16: =BU16-CC16 -> 341001.64 | CE16: =PV(CB16,360,-CA16) -> 291324.32 | CG16: =BZ16-BY16-BX16 -> 2400.2775 | CH16: =PV(CB16,360,-CG16) -> 389834.41 | CI16: =BU16*0.03 -> 19240.08 | CJ16: =BU16-CI16-CH16 -> 232261.51 | CK16: =CJ16/BU16 -> 0.36215262 | CM16: =CA16 -> 1793.734 | CN16: =(CC16*1%)/12 -> 250.27863 | CO16: =CM16+CN16+BX16+BY16 -> 2570.9309 | CP16: =VLOOKUP(BS16,'Paste Snowflake Data Here'!$B$2:$K$21,10,FALSE) -> 1701 | CQ16: =CP16-CO16 -> -869.93094
B17: Arizona | D17: =_xlfn.XLOOKUP($B17,'Paste Snowflake Data Here'!$B$3:$B$1048576,'Paste Snowflake Data Here'!$D$3:$D$1048576) -> 7598046 | F17: =_xlfn.XLOOKUP($B17,'Paste Snowflake Data Here'!$B$3:$B$1048576,'Paste Snowflake Data Here'!$I$3:$I$1048576) -> 82768 | G17: =_xlfn.XLOOKUP($B17,'Paste Snowflake Data Here'!$B$3:$B$1048576,'Paste Snowflake Data Here'!$J$3:$J$1048576) -> 429848 | H17: =_xlfn.XLOOKUP($B17,'Paste Snowflake Data Here'!$B$3:$B$1048576,'Paste Snowflake Data Here'!$K$3:$K$1048576) -> 1509 | K17: =IFERROR(VLOOKUP(LEFT(B17,FIND("County",B17)-2),CaseShiller30,5,0)*0.01,$K$3) -> 0.05 | L17: =$F17*$L$3 -> 82768 | M17: =$G17*$M$3 -> 429848 | N17: =AND(AF17<$AF$3,AG17<$AG$3) -> FALSE | O17: =AND(AP17<$AP$3,AQ17<$AQ$3) -> TRUE | P17: =AND(N17=FALSE,O17) -> TRUE | Q17: =AH17 -> 128954.4 | R17: =AU17 -> 0 | S17: =AR17 -> 0 | T17: =AZ17 -> 247520.91 | U17: =BA17 -> 19.194452 | V17: =AX17 -> 210053.13 | W17: =AY17 -> 1.6288946 | X17: =$X$3*M17 -> 12895.44 | Y17: =$Y$3 -> 0.0625 | Z17: =M17-X17 -> 416952.56 | AA17: =Z17*'PMI Rate Est'!$J$6/12 -> 406.52875 | AB17: ='Taxes & Ins by State'!B4*M17/12 -> 157.61093 | AC17: ='Taxes & Ins by State'!M14*M17/12 -> 187.08333 | AD17: =MAX(J17*Y17/12,0) -> 0 | AE17: =-PMT(Y17/12,360,Z17) -> 2567.2486 | AF17: =SUM(AE17,AC17,AB17,AA17)/(L17/12) -> 0.48112386 | AG17: =SUM(AE17,AC17,AB17,AA17,AD17)/(L17/12) -> 0.48112386 | AH17: =M17*$AH$3 -> 128954.4 | AI17: =Y17+$AI$3 -> 0.0625 | AJ17: =M17-X17-AH17 -> 287998.16 | AK17: =AH17*$AK$3/12 -> 0 | AL17: =AB17 -> 157.61093 | AM17: =AC17 -> 187.08333 | AN17: =MAX(J17*Y17/12,0) -> 0 | AO17: =-PMT(AI17/12,360,AJ17) -> 1773.2542 | AP17: =SUM(AO17,AM17,AL17)/(L17/12) -> 0.30706773 | AQ17: =SUM(AO17,AM17,AL17,AK17,AN17)/(L17/12) -> 0.30706773 | AR17: =$AR$3*AK17*12 -> 0 | AS17: =$AS$3*(M17-X17) -> 8339.0512 | AT17: =$AT$3*(AH17) -> 3868.632 | AU17: =$AU$3*SUM(AR17,AS17,AT17) -> 0 | AV17: =AU17/M17 -> 0 | AW17: =POWER(1+K17,10)*M17 -> 700177.1 | AX17: =POWER(1+K17,10)*AH17 -> 210053.13 | AY17: =AX17/AH17 -> 1.6288946 | AZ17: =AW17-AX17-FV(AI17/12,(10*12),AO17,-AJ17) -> 247520.91 | BA17: =AZ17/X17 -> 19.194452 | BE17: =(L17/12)*35% -> 2414.0667 | BF17: =BE17-AC17-AB17-AA17 -> 1662.8437 | BG17: =$Y$3/12 -> 0.0052083333 | BH17: =(BG17*(1+BG17)^360) / (((1+BG17)^360)-1) -> 0.006157172 | BI17: =PV(BG17, 360, -BF17) -> 270066.14 | BK17: =BE17-AB17-AC17 -> 2069.3724 | BL17: =BK17/BH17 -> 336091.37 | BN17: =M17-BI17-X17 -> 146886.42 | BO17: =BN17/M17 -> 0.34171713 | BP17: =M17-BL17-X17 -> 80861.186 | BS17: =B17 -> Arizona | BT17: =L17 -> 82768 | BU17: =M17 -> 429848 | BV17: =H17 -> 1509 | BW17: =AA17 -> 406.52875 | BX17: =AB17 -> 157.61093 | BY17: =AC17 -> 187.08333 | BZ17: =(BT17/12)*$BT$2 -> 2414.0667 | CA17: =BZ17-BW17-BX17-BY17 -> 1662.8437 | CB17: =6.25%/12 -> 0.0052083333 | CC17: =CE17/0.97 -> 278418.7 | CD17: =BU17-CC17 -> 151429.3 | CE17: =PV(CB17,360,-CA17) -> 270066.14 | CG17: =BZ17-BY17-BX17 -> 2069.3724 | CH17: =PV(CB17,360,-CG17) -> 336091.37 | CI17: =BU17*0.03 -> 12895.44 | CJ17: =BU17-CI17-CH17 -> 80861.186 | CK17: =CJ17/BU17 -> 0.18811577 | CM17: =CA17 -> 1662.8437 | CN17: =(CC17*1%)/12 -> 232.01558 | CO17: =CM17+CN17+BX17+BY17 -> 2239.5535 | CP17: =VLOOKUP(BS17,'Paste Snowflake Data Here'!$B$2:$K$21,10,FALSE) -> 1509 | CQ17: =CP17-CO17 -> -730.5535
B18: Kansas | D18: =_xlfn.XLOOKUP($B18,'Paste Snowflake Data Here'!$B$3:$B$1048576,'Paste Snowflake Data Here'!$D$3:$D$1048576) -> 2967337 | F18: =_xlfn.XLOOKUP($B18,'Paste Snowflake Data Here'!$B$3:$B$1048576,'Paste Snowflake Data Here'!$I$3:$I$1048576) -> 72975 | G18: =_xlfn.XLOOKUP($B18,'Paste Snowflake Data Here'!$B$3:$B$1048576,'Paste Snowflake Data Here'!$J$3:$J$1048576) -> 243477 | H18: =_xlfn.XLOOKUP($B18,'Paste Snowflake Data Here'!$B$3:$B$1048576,'Paste Snowflake Data Here'!$K$3:$K$1048576) -> 899 | K18: =IFERROR(VLOOKUP(LEFT(B18,FIND("County",B18)-2),CaseShiller30,5,0)*0.01,$K$3) -> 0.05 | L18: =$F18*$L$3 -> 72975 | M18: =$G18*$M$3 -> 243477 | N18: =AND(AF18<$AF$3,AG18<$AG$3) -> FALSE | O18: =AND(AP18<$AP$3,AQ18<$AQ$3) -> TRUE | P18: =AND(N18=FALSE,O18) -> TRUE | Q18: =AH18 -> 73043.1 | R18: =AU18 -> 0 | S18: =AR18 -> 0 | T18: =AZ18 -> 140202.23 | U18: =BA18 -> 19.194452 | V18: =AX18 -> 118979.51 | W18: =AY18 -> 1.6288946 | X18: =$X$3*M18 -> 7304.31 | Y18: =$Y$3 -> 0.0625 | Z18: =M18-X18 -> 236172.69 | AA18: =Z18*'PMI Rate Est'!$J$6/12 -> 230.26837 | AB18: ='Taxes & Ins by State'!B17*M18/12 -> 241.44803 | AC18: ='Taxes & Ins by State'!M17*M18/12 -> 357.25 | AD18: =MAX(J18*Y18/12,0) -> 0 | AE18: =-PMT(Y18/12,360,Z18) -> 1454.1559 | AF18: =SUM(AE18,AC18,AB18,AA18)/(L18/12) -> 0.37543634 | AG18: =SUM(AE18,AC18,AB18,AA18,AD18)/(L18/12) -> 0.37543634 | AH18: =M18*$AH$3 -> 73043.1 | AI18: =Y18+$AI$3 -> 0.0625 | AJ18: =M18-X18-AH18 -> 163129.59 | AK18: =AH18*$AK$3/12 -> 0 | AL18: =AB18 -> 241.44803 | AM18: =AC18 -> 357.25 | AN18: =MAX(J18*Y18/12,0) -> 0 | AO18: =-PMT(AI18/12,360,AJ18) -> 1004.4169 | AP18: =SUM(AO18,AM18,AL18)/(L18/12) -> 0.26361603 | AQ18: =SUM(AO18,AM18,AL18,AK18,AN18)/(L18/12) -> 0.26361603 | AR18: =$AR$3*AK18*12 -> 0 | AS18: =$AS$3*(M18-X18) -> 4723.4538 | AT18: =$AT$3*(AH18) -> 2191.293 | AU18: =$AU$3*SUM(AR18,AS18,AT18) -> 0 | AV18: =AU18/M18 -> 0 | AW18: =POWER(1+K18,10)*M18 -> 396598.38 | AX18: =POWER(1+K18,10)*AH18 -> 118979.51 | AY18: =AX18/AH18 -> 1.6288946 | AZ18: =AW18-AX18-FV(AI18/12,(10*12),AO18,-AJ18) -> 140202.23 | BA18: =AZ18/X18 -> 19.194452 | BE18: =(L18/12)*35% -> 2128.4375 | BF18: =BE18-AC18-AB18-AA18 -> 1299.4711 | BG18: =$Y$3/12 -> 0.0052083333 | BH18: =(BG18*(1+BG18)^360) / (((1+BG18)^360)-1) -> 0.006157172 | BI18: =PV(BG18, 360, -BF18) -> 211049.99 | BK18: =BE18-AB18-AC18 -> 1529.7395 | BL18: =BK18/BH18 -> 248448.39 | BN18: =M18-BI18-X18 -> 25122.698 | BO18: =BN18/M18 -> 0.10318304 | BP18: =M18-BL18-X18 -> -12275.701 | BS18: =B18 -> Kansas | BT18: =L18 -> 72975 | BU18: =M18 -> 243477 | BV18: =H18 -> 899 | BW18: =AA18 -> 230.26837 | BX18: =AB18 -> 241.44803 | BY18: =AC18 -> 357.25 | BZ18: =(BT18/12)*$BT$2 -> 2128.4375 | CA18: =BZ18-BW18-BX18-BY18 -> 1299.4711 | CB18: =6.25%/12 -> 0.0052083333 | CC18: =CE18/0.97 -> 217577.31 | CD18: =BU18-CC18 -> 25899.689 | CE18: =PV(CB18,360,-CA18) -> 211049.99 | CG18: =BZ18-BY18-BX18 -> 1529.7395 | CH18: =PV(CB18,360,-CG18) -> 248448.39 | CI18: =BU18*0.03 -> 7304.31 | CJ18: =BU18-CI18-CH18 -> -12275.701 | CK18: =CJ18/BU18 -> -0.050418317 | CM18: =CA18 -> 1299.4711 | CN18: =(CC18*1%)/12 -> 181.31443 | CO18: =CM18+CN18+BX18+BY18 -> 2079.4836 | CP18: =VLOOKUP(BS18,'Paste Snowflake Data Here'!$B$2:$K$21,10,FALSE) -> 899 | CQ18: =CP18-CO18 -> -1180.4836
B19: Michigan | D19: =_xlfn.XLOOKUP($B19,'Paste Snowflake Data Here'!$B$3:$B$1048576,'Paste Snowflake Data Here'!$D$3:$D$1048576) -> 10042188 | F19: =_xlfn.XLOOKUP($B19,'Paste Snowflake Data Here'!$B$3:$B$1048576,'Paste Snowflake Data Here'!$I$3:$I$1048576) -> 72645 | G19: =_xlfn.XLOOKUP($B19,'Paste Snowflake Data Here'!$B$3:$B$1048576,'Paste Snowflake Data Here'!$J$3:$J$1048576) -> 259246 | H19: =_xlfn.XLOOKUP($B19,'Paste Snowflake Data Here'!$B$3:$B$1048576,'Paste Snowflake Data Here'!$K$3:$K$1048576) -> 1004 | K19: =IFERROR(VLOOKUP(LEFT(B19,FIND("County",B19)-2),CaseShiller30,5,0)*0.01,$K$3) -> 0.05 | L19: =$F19*$L$3 -> 72645 | M19: =$G19*$M$3 -> 259246 | N19: =AND(AF19<$AF$3,AG19<$AG$3) -> FALSE | O19: =AND(AP19<$AP$3,AQ19<$AQ$3) -> TRUE | P19: =AND(N19=FALSE,O19) -> TRUE | Q19: =AH19 -> 77773.8 | R19: =AU19 -> 0 | S19: =AR19 -> 0 | T19: =AZ19 -> 149282.55 | U19: =BA19 -> 19.194452 | V19: =AX19 -> 126685.32 | W19: =AY19 -> 1.6288946 | X19: =$X$3*M19 -> 7777.38 | Y19: =$Y$3 -> 0.0625 | Z19: =M19-X19 -> 251468.62 | AA19: =Z19*'PMI Rate Est'!$J$6/12 -> 245.1819 | AB19: ='Taxes & Ins by State'!B23*M19/12 -> 248.44408 | AC19: ='Taxes & Ins by State'!M19*M19/12 -> 176.41667 | AD19: =MAX(J19*Y19/12,0) -> 0 | AE19: =-PMT(Y19/12,360,Z19) -> 1548.3355 | AF19: =SUM(AE19,AC19,AB19,AA19)/(L19/12) -> 0.36644695 | AG19: =SUM(AE19,AC19,AB19,AA19,AD19)/(L19/12) -> 0.36644695 | AH19: =M19*$AH$3 -> 77773.8 | AI19: =Y19+$AI$3 -> 0.0625 | AJ19: =M19-X19-AH19 -> 173694.82 | AK19: =AH19*$AK$3/12 -> 0 | AL19: =AB19 -> 248.44408 | AM19: =AC19 -> 176.41667 | AN19: =MAX(J19*Y19/12,0) -> 0 | AO19: =-PMT(AI19/12,360,AJ19) -> 1069.4689 | AP19: =SUM(AO19,AM19,AL19)/(L19/12) -> 0.24684363 | AQ19: =SUM(AO19,AM19,AL19,AK19,AN19)/(L19/12) -> 0.24684363 | AR19: =$AR$3*AK19*12 -> 0 | AS19: =$AS$3*(M19-X19) -> 5029.3724 | AT19: =$AT$3*(AH19) -> 2333.214 | AU19: =$AU$3*SUM(AR19,AS19,AT19) -> 0 | AV19: =AU19/M19 -> 0 | AW19: =POWER(1+K19,10)*M19 -> 422284.42 | AX19: =POWER(1+K19,10)*AH19 -> 126685.32 | AY19: =AX19/AH19 -> 1.6288946 | AZ19: =AW19-AX19-FV(AI19/12,(10*12),AO19,-AJ19) -> 149282.55 | BA19: =AZ19/X19 -> 19.194452 | BE19: =(L19/12)*35% -> 2118.8125 | BF19: =BE19-AC19-AB19-AA19 -> 1448.7698 | BG19: =$Y$3/12 -> 0.0052083333 | BH19: =(BG19*(1+BG19)^360) / (((1+BG19)^360)-1) -> 0.006157172 | BI19: =PV(BG19, 360, -BF19) -> 235297.93 | BK19: =BE19-AB19-AC19 -> 1693.9517 | BL19: =BK19/BH19 -> 275118.47 | BN19: =M19-BI19-X19 -> 16170.687 | BO19: =BN19/M19 -> 0.06237584 | BP19: =M19-BL19-X19 -> -23649.851 | BS19: =B19 -> Michigan | BT19: =L19 -> 72645 | BU19: =M19 -> 259246 | BV19: =H19 -> 1004 | BW19: =AA19 -> 245.1819 | BX19: =AB19 -> 248.44408 | BY19: =AC19 -> 176.41667 | BZ19: =(BT19/12)*$BT$2 -> 2118.8125 | CA19: =BZ19-BW19-BX19-BY19 -> 1448.7698 | CB19: =6.25%/12 -> 0.0052083333 | CC19: =CE19/0.97 -> 242575.19 | CD19: =BU19-CC19 -> 16670.811 | CE19: =PV(CB19,360,-CA19) -> 235297.93 | CG19: =BZ19-BY19-BX19 -> 1693.9517 | CH19: =PV(CB19,360,-CG19) -> 275118.47 | CI19: =BU19*0.03 -> 7777.38 | CJ19: =BU19-CI19-CH19 -> -23649.851 | CK19: =CJ19/BU19 -> -0.091225521 | CM19: =CA19 -> 1448.7698 | CN19: =(CC19*1%)/12 -> 202.14599 | CO19: =CM19+CN19+BX19+BY19 -> 2075.7766 | CP19: =VLOOKUP(BS19,'Paste Snowflake Data Here'!$B$2:$K$21,10,FALSE) -> 1004 | CQ19: =CP19-CO19 -> -1071.7766
